Workbook

Sheet Guideline
A1: HƯỚNG DẪN SỬ DỤNG BỘ TEST CASE PRODUCTION — AILAB SURVEY
A4: 1. Mục tiêu | B4: Bộ test dùng để người khác trực tiếp dùng hệ thống và xác nhận từng chức năng. Không phải bộ test nội dung bài kiểm tra.
A5: 2. Thứ tự sử dụng | B5: Cover → FunctionList → Test Report → UT01…UT17. Bài mẫu chỉ minh họa cách đọc ma trận và không được tính vào report.
A6: 3. Một nguồn test duy nhất | B6: Mỗi test case chỉ tồn tại một lần trong đúng sheet chức năng. Không có bộ UAT riêng và không lặp bảng chi tiết phía dưới.
A7: 4. Loại test | B7: N = Normal: luồng đúng; A = Abnormal: dữ liệu/quyền/lỗi; B = Boundary: giá trị biên.
A8: 5. Trạng thái | B8: Passed = đúng kỳ vọng; Failed = sai kỳ vọng; Blocked = chưa thể chạy do môi trường/feature. Ô trống = Untested.
A9: 6. Cách chạy một cột test | B9: Đọc từ trên xuống: Tình huống → Tiền điều kiện → Input 1/2 → Bước 1…4 → Kết quả mong đợi → Lỗi/Thông báo → Điểm kiểm tra.
A10: 7. Khi Failed | B10: Ghi Defect ID ở dòng cuối; bằng chứng ảnh/log dùng cùng Defect ID. Không sửa Expected Result để khớp lỗi thực tế.
A11: 8. Khi Blocked | B11: Ghi lý do ngoài file hoặc trong Defect ID. Riêng AI Result Chat: nếu build chưa có feature, đánh Blocked, không đánh Failed.
A12: 9. Tiêu chí chấp nhận release | B12: Không còn Failed Critical chưa xử lý; Blocked có quyết định rõ; coverage đạt kế hoạch; các luồng core tạo survey, import, response, analysis và quyền đã chạy.
A13: 10. Nguồn mã | B13: Bộ test bám snapshot mã nguồn; trạng thái Verified/Partial/GAP được ghi trực tiếp trong FunctionList và metadata từng UT.
A15: Repository | B15: https://github.com/Royal2005-coder/formailab
A16: Source commit | B16: ef92d78aa86916e6fbf4bc8a43044a4a4328154d
... A21: 13. Nguyên tắc không nhân đôi | B21: Hai bảng phụ chỉ là tài liệu hỗ trợ thiết kế/thực thi; Test Report vẫn tính đúng 224 test case production hiện tại.

Sheet Cover
A1: AILAB SURVEY UNIT TEST CASE
A7: Project Name | B7: FormaiLab — AI LAB Survey Engine | D7: Creator | E7: QA / UAT Team
A8: Project Code | B8: AILAB-AUT | D8: Reviewer/Approver
A9: Document Code | B9: AILAB-AUT-UTC-v5.0 | D9: Issue Date | E9: 46242
A10: Version | B10: 5.0 | D10: Source Commit | E10: ef92d78aa86916e6fbf4bc8a43044a4a4328154d
A12: Record of change
A13: Effective Date | B13: Version | C13: Change Item | D13: *A,D,M | E13: Change description | F13: Reference
A14: 46242 | B14: 5.0 | C14: M | D14: M | E14: Master test case hệ thống AILAB Survey gồm built in module và customize module: CSV Import và AI Native | F14: Unified production test case
A18: Repository | B18: https://github.com/Royal2005-coder/formailab
A19: Snapshot URL | B19: https://github.com/Royal2005-coder/formailab/tree/ef92d78aa86916e6fbf4bc8a43044a4a4328154d
A20: Total production test cases | B20: 224

Sheet FunctionList
A2: UNIT TEST CASE LIST
A4: Project Name | D4: FormaiLab — AI LAB Survey Engine
A5: Project Code | D5: AILAB-AUT
A6: Normal number of Test cases/KLOC | D6: 100
A7: Test Environment Setup Description | D7: Local/Staging/Prod-like; Chrome/Edge; PostgreSQL; Redis; Storage; SMTP; AI provider khi test AI.
A10: No | B10: Requirement Name | C10: Class Name | D10: Function Name | E10: Function Code(Optional) | F10: Sheet Name | G10: Description | H10: Pre-Condition
A11: 1 | B11: Kiểm tra đăng nhập, đăng ký, quên mật khẩu, OAuth, đăng xuất và bảo vệ route. | C11: AuthModule | D11: Xác thực & Phiên đăng nhập | E11: AUTH-001 | F11: =HYPERLINK("#'UT01_XacThuc'!A1","UT01_XacThuc") -> UT01_XacThuc | G11: Xác thực người dùng từ góc nhìn end user; bao phủ luồng đúng, lỗi nhập liệu và phiên truy cập. Verified | apps/web/modules/auth | H11: Ứng dụng, DB và email/OAuth test đã cấu hình theo từng case.
A12: 2 | B12: Kiểm tra vòng đời tổ chức, mời thành viên, vai trò, nhóm và quyền quản trị tổ chức. | C12: OrganizationModule | D12: Tổ chức, Thành viên & Nhóm | E12: ORG-001 | F12: =HYPERLINK("#'UT02_ToChuc'!A1","UT02_ToChuc") -> UT02_ToChuc | G12: Quản trị organization và membership ở mức người dùng/manager. Verified | apps/web/modules/organization | H12: Đã đăng nhập; chuẩn bị tài khoản Owner, Manager và Member.
A13: 3 | B13: Kiểm tra CRUD workspace, chuyển context, read/readWrite và cách ly dữ liệu giữa workspace. | C13: WorkspaceAccessModule | D13: Workspace & Phân quyền truy cập | E13: WKSP-001 | F13: =HYPERLINK("#'UT03_Workspace_RBAC'!A1","UT03_Workspace_RBAC") -> UT03_Workspace_RBAC | G13: Hợp nhất kiểm thử Workspace và RBAC để tránh lặp case quyền ở nhiều nơi. Verified | apps/web/app/(app)/workspaces | H13: Có organization và tối thiểu hai workspace A/B; tài khoản nhiều mức quyền.
A14: 4 | B14: Kiểm tra hành trình từ workspace đến Surveys, AI LAB, Responses và Analysis. | C14: NavigationModule | D14: Dashboard, Danh sách & Điều hướng | E14: NAV-001 | F14: =HYPERLINK("#'UT04_Dashboard_DieuHuong'!A1","UT04_Dashboard_DieuHuong") -> UT04_Dashboard_DieuHuong | G14: Điều hướng, empty state, browser navigation và tính nhất quán context. Verified | apps/web/modules/survey/list/components/survey-list.tsx | H14: Có tài khoản, workspace và dữ liệu survey theo từng case.
A15: 5 | B15: Kiểm tra vòng đời survey thủ công từ tạo mới đến câu hỏi, preview, publish, archive và xóa. | C15: SurveyModule | D15: Tạo khảo sát thủ công, Editor & Publish | E15: SURV-001 | F15: =HYPERLINK("#'UT05_Survey_ThuCong'!A1","UT05_Survey_ThuCong") -> UT05_Survey_ThuCong | G15: Module survey duy nhất, thay cho UT_KhaoSat và UT_SurveyManual trước đây. Verified | apps/web/modules/survey | H15: User có quyền readWrite trong workspace.
A16: 6 | B16: Kiểm tra import ngân hàng câu hỏi: validate, diagnostics, preview, commit, checksum và idempotency. | C16: AiLabImportModule | D16: Import CSV/XLS/XLSX, Preview & Commit | E16: IMP-001 | F16: =HYPERLINK("#'UT06_Import_CSV_XLSX'!A1","UT06_Import_CSV_XLSX") -> UT06_Import_CSV_XLSX | G16: Luồng AI LAB Survey Import đã xác minh ở actions/actions.schema. Verified | apps/web/modules/ai-lab-survey/actions.ts | H16: Workspace tồn tại; user có quyền phù hợp; có file fixture.
A17: 7 | B17: Kiểm tra cấu trúc test bank và Adaptive Engine sau import từ góc nhìn end user. | C17: AdaptiveTestBankModule | D17: Test Bank, Relevance, Score & Routing | E17: TB-001 | F17: =HYPERLINK("#'UT07_TestBank_Adaptive'!A1","UT07_TestBank_Adaptive") -> UT07_TestBank_Adaptive | G17: Group/Question/Option, matrix, score variable, relevance và route boundary. Verified | packages/survey-compiler/src/import-csv.ts | H17: Có fixture test bank CSV/XLSX hợp lệ hoặc cố ý lỗi.
A18: 8 | B18: Kiểm tra người trả lời mở survey, nhập dữ liệu, gửi, cập nhật trạng thái và tính toàn vẹn response. | C18: ResponseModule | D18: Public Survey, Response & Submission | E18: RESP-001 | F18: =HYPERLINK("#'UT08_PhanHoi'!A1","UT08_PhanHoi") -> UT08_PhanHoi | G18: Tập trung outcome người trả lời; không lặp phần editor. Verified | apps/web/lib/response/service.ts | H18: Survey đã publish và có public link.
A19: 9 | B19: Kiểm tra tổng quan phản hồi, bộ lọc, KPI, biểu đồ và export dữ liệu. | C19: AnalysisModule | D19: Phân tích, Insights, Chart & Export | E19: ANLY-001 | F19: =HYPERLINK("#'UT09_PhanTich_Insights'!A1","UT09_PhanTich_Insights") -> UT09_PhanTich_Insights | G19: Hợp nhất UT_PhanTich và UT_InsightsExport; một nguồn report duy nhất. Verified/Risk | apps/web/modules/ai-lab-survey/components/insights-dashboard.tsx | H19: Survey/AI LAB có fixture responses biết trước.
A20: 10 | B20: Kiểm tra AI tạo survey bằng prompt và file context, boundary prompt, entitlement và lỗi provider. | C20: AIGenerateModule | D20: AI Native - Tạo Survey từ mô tả/tài liệu | E20: AI-GEN-001 | F20: =HYPERLINK("#'UT10_AI_TaoSurvey'!A1","UT10_AI_TaoSurvey") -> UT10_AI_TaoSurvey | G20: AI survey generation qua V3 payload validation và editor. Verified | apps/web/modules/survey/components/template-list/components/create-with-ai-form.tsx | H20: AI provider/entitlement cấu hình theo từng case.
A21: 11 | B21: Kiểm tra availability, quyền và dịch survey đa ngôn ngữ bằng AI. | C21: AITranslationModule | D21: AI Native - Dịch khảo sát | E21: AI-TR-001 | F21: =HYPERLINK("#'UT11_AI_Dich'!A1","UT11_AI_Dich") -> UT11_AI_Dich | G21: AI Translation ở cấp field, giữ source và target rõ ràng. Verified | apps/web/modules/ee/ai-translation/lib/actions.ts | H21: Survey có nội dung nguồn; AI config theo case.
A22: 12 | B22: Kiểm tra hiển thị enrichment sentiment/emotions trên feedback record. | C22: AISentimentModule | D22: AI Native - Sentiment & Emotions | E22: AI-SEN-001 | F22: =HYPERLINK("#'UT12_AI_Sentiment'!A1","UT12_AI_Sentiment") -> UT12_AI_Sentiment | G22: UI enrichment read-only; pipeline tạo enrichment được đánh Partial nếu môi trường chưa có job AI. Partial | apps/web/modules/ee/unify-feedback/components/feedback-record-form-drawer.tsx | H22: Có Unify Feedback records đã/chưa enrichment.
A23: 13 | B23: Kiểm tra gate dữ liệu, embedding, generate taxonomy và quản trị node. | C23: AITaxonomyModule | D23: AI Native - Topic/Subtopic Tree | E23: AI-TOP-001 | F23: =HYPERLINK("#'UT13_AI_TopicTree'!A1","UT13_AI_TopicTree") -> UT13_AI_TopicTree | G23: Cây chủ đề/subtopic trên open-text feedback; boundary 750 và embedding threshold 50. Verified | apps/web/modules/ee/unify-feedback/topics-subtopics/components/topics-subtopics-container.tsx | H23: Có Unify Feedback directory và fixture counts theo case.
A24: 14 | B24: Acceptance contract cho hỏi-đáp trên dữ liệu survey; nếu build chưa có entry point thì đánh Blocked. | C24: AIResultChatModule | D24: AI Native - Chat với kết quả khảo sát | E24: AI-CHAT-001 | F24: =HYPERLINK("#'UT14_AI_ResultChat'!A1","UT14_AI_ResultChat") -> UT14_AI_ResultChat | G24: Không giả định implementation chưa xác minh. Tab này nằm trong cùng bộ test để quản lý gap production. GAP | GAP: chưa xác minh code path | H24: Chỉ thực thi khi build có AI Chat trên Results/Analysis.
A25: 15 | B25: Kiểm tra webhook và các kết nối ngoài theo quyền, callback, lỗi và thu hồi kết nối. | C25: IntegrationModule | D25: Webhook & Tích hợp ngoài | E25: INTG-001 | F25: =HYPERLINK("#'UT15_TichHop'!A1","UT15_TichHop") -> UT15_TichHop | G25: Webhook + OAuth integrations như Slack/Notion/Airtable/Google Sheets theo cấu hình build. Verified | apps/web/modules/integrations | H25: Có workspace quyền quản trị và sandbox account của dịch vụ ngoài.
A26: 16 | B26: Kiểm tra xác thực API, CRUD survey/response, validation, phân quyền, pagination và rate/error contract. | C26: APIModule | D26: REST API v1/v3 & API Key | E26: API-001 | F26: =HYPERLINK("#'UT16_API'!A1","UT16_API") -> UT16_API | G26: Acceptance API ở mức consumer; dùng API key test. Verified | apps/web/app/api | H26: App đang chạy; có API key và tool HTTP/Postman/curl.
A27: 17 | B27: Kiểm tra upload/download/delete file, signed URL và các email hệ thống chính. | C27: StorageEmailModule | D27: Lưu trữ file & Email hệ thống | E27: STGE-001 | F27: =HYPERLINK("#'UT17_LuuTru_Email'!A1","UT17_LuuTru_Email") -> UT17_LuuTru_Email | G27: Storage + SMTP acceptance ở mức end user/admin. Verified | apps/web/modules | H27: S3/local storage và SMTP test đã cấu hình.

Sheet Test Report
A2: UNIT TEST REPORT
M3: Status | N3: Count
A4: Project Name | B4: FormaiLab — AI LAB Survey Engine | C4: FormaiLab — AI LAB Survey Engine | D4: Creator | E4: QA / UAT Team | F4: Creator | H4: QA / UAT Team | M4: Passed | N4: =C30 -> 1
A5: Project Code | B5: AILAB-AUT | C5: AILAB-AUT | D5: Reviewer/Approver | F5: Reviewer/Approver | M5: Failed | N5: =D30 -> 1
A6: Document Code | B6: AILAB-AUT-UTC-v5.0 | C6: AILAB-AUT-UTC-v5.0 | D6: Issue Date | E6: 46242 | F6: Issue Date | H6: 46242 | M6: Blocked | N6: =E30 -> 1
A7: Notes | B7: Một bộ test duy nhất theo template; Bài mẫu không tính vào báo cáo. | C7: Một bộ test duy nhất theo template; Bài mẫu không tính vào báo cáo. | D7: Environment | E7: Local / Staging / Prod-like | F7: Environment | H7: Local / Staging / Prod-like | M7: Untested | N7: =F30 -> 221
A8: Source Commit | B8: ef92d78aa86916e6fbf4bc8a43044a4a4328154d | C8: ef92d78aa86916e6fbf4bc8a43044a4a4328154d | D8: Repository | E8: https://github.com/Royal2005-coder/formailab | F8: Repository | H8: https://github.com/Royal2005-coder/formailab | M8: Total | N8: =J30 -> 224
M10: Test Type | N10: Count
A11: No | B11: Function code | C11: Passed | D11: Failed | E11: Blocked | F11: Untested | G11: N | H11: A | I11: B | J11: Total Test Cases | K11: Coverage | M11: Normal (N) | N11: =G30 -> 112
A12: 1 | B12: =HYPERLINK("#'UT01_XacThuc'!A1","AUTH-001") -> AUTH-001 | C12: =UT01_XacThuc!A7 -> 1 | D12: =UT01_XacThuc!C7 -> 1 | E12: =UT01_XacThuc!E7 -> 1 | F12: =UT01_XacThuc!G7 -> 9 | G12: =UT01_XacThuc!I7 -> 5 | H12: =UT01_XacThuc!K7 -> 5 | I12: =UT01_XacThuc!M7 -> 2 | J12: =UT01_XacThuc!O7 -> 12 | K12: =IF(J12=0,0,(C12+D12+E12)/J12) -> 0.25 | M12: Abnormal (A) | N12: =H30 -> 72
A13: 2 | B13: =HYPERLINK("#'UT02_ToChuc'!A1","ORG-001") -> ORG-001 | C13: =UT02_ToChuc!A7 -> 0 | D13: =UT02_ToChuc!C7 -> 0 | E13: =UT02_ToChuc!E7 -> 0 | F13: =UT02_ToChuc!G7 -> 12 | G13: =UT02_ToChuc!I7 -> 7 | H13: =UT02_ToChuc!K7 -> 5 | I13: =UT02_ToChuc!M7 -> 0 | J13: =UT02_ToChuc!O7 -> 12 | K13: =IF(J13=0,0,(C13+D13+E13)/J13) -> 0 | M13: Boundary (B) | N13: =I30 -> 40
A14: 3 | B14: =HYPERLINK("#'UT03_Workspace_RBAC'!A1","WKSP-001") -> WKSP-001 | C14: =UT03_Workspace_RBAC!A7 -> 0 | D14: =UT03_Workspace_RBAC!C7 -> 0 | E14: =UT03_Workspace_RBAC!E7 -> 0 | F14: =UT03_Workspace_RBAC!G7 -> 15 | G14: =UT03_Workspace_RBAC!I7 -> 9 | H14: =UT03_Workspace_RBAC!K7 -> 4 | I14: =UT03_Workspace_RBAC!M7 -> 2 | J14: =UT03_Workspace_RBAC!O7 -> 15 | K14: =IF(J14=0,0,(C14+D14+E14)/J14) -> 0
A15: 4 | B15: =HYPERLINK("#'UT04_Dashboard_DieuHuong'!A1","NAV-001") -> NAV-001 | C15: =UT04_Dashboard_DieuHuong!A7 -> 0 | D15: =UT04_Dashboard_DieuHuong!C7 -> 0 | E15: =UT04_Dashboard_DieuHuong!E7 -> 0 | F15: =UT04_Dashboard_DieuHuong!G7 -> 10 | G15: =UT04_Dashboard_DieuHuong!I7 -> 5 | H15: =UT04_Dashboard_DieuHuong!K7 -> 1 | I15: =UT04_Dashboard_DieuHuong!M7 -> 4 | J15: =UT04_Dashboard_DieuHuong!O7 -> 10 | K15: =IF(J15=0,0,(C15+D15+E15)/J15) -> 0
A16: 5 | B16: =HYPERLINK("#'UT05_Survey_ThuCong'!A1","SURV-001") -> SURV-001 | C16: =UT05_Survey_ThuCong!A7 -> 0 | D16: =UT05_Survey_ThuCong!C7 -> 0 | E16: =UT05_Survey_ThuCong!E7 -> 0 | F16: =UT05_Survey_ThuCong!G7 -> 15 | G16: =UT05_Survey_ThuCong!I7 -> 13 | H16: =UT05_Survey_ThuCong!K7 -> 2 | I16: =UT05_Survey_ThuCong!M7 -> 0 | J16: =UT05_Survey_ThuCong!O7 -> 15 | K16: =IF(J16=0,0,(C16+D16+E16)/J16) -> 0
A17: 6 | B17: =HYPERLINK("#'UT06_Import_CSV_XLSX'!A1","IMP-001") -> IMP-001 | C17: =UT06_Import_CSV_XLSX!A7 -> 0 | D17: =UT06_Import_CSV_XLSX!C7 -> 0 | E17: =UT06_Import_CSV_XLSX!E7 -> 0 | F17: =UT06_Import_CSV_XLSX!G7 -> 15 | G17: =UT06_Import_CSV_XLSX!I7 -> 5 | H17: =UT06_Import_CSV_XLSX!K7 -> 7 | I17: =UT06_Import_CSV_XLSX!M7 -> 3 | J17: =UT06_Import_CSV_XLSX!O7 -> 15 | K17: =IF(J17=0,0,(C17+D17+E17)/J17) -> 0
A18: 7 | B18: =HYPERLINK("#'UT07_TestBank_Adaptive'!A1","TB-001") -> TB-001 | C18: =UT07_TestBank_Adaptive!A7 -> 0 | D18: =UT07_TestBank_Adaptive!C7 -> 0 | E18: =UT07_TestBank_Adaptive!E7 -> 0 | F18: =UT07_TestBank_Adaptive!G7 -> 15 | G18: =UT07_TestBank_Adaptive!I7 -> 10 | H18: =UT07_TestBank_Adaptive!K7 -> 2 | I18: =UT07_TestBank_Adaptive!M7 -> 3 | J18: =UT07_TestBank_Adaptive!O7 -> 15 | K18: =IF(J18=0,0,(C18+D18+E18)/J18) -> 0
A19: 8 | B19: =HYPERLINK("#'UT08_PhanHoi'!A1","RESP-001") -> RESP-001 | C19: =UT08_PhanHoi!A7 -> 0 | D19: =UT08_PhanHoi!C7 -> 0 | E19: =UT08_PhanHoi!E7 -> 0 | F19: =UT08_PhanHoi!G7 -> 15 | G19: =UT08_PhanHoi!I7 -> 7 | H19: =UT08_PhanHoi!K7 -> 4 | I19: =UT08_PhanHoi!M7 -> 4 | J19: =UT08_PhanHoi!O7 -> 15 | K19: =IF(J19=0,0,(C19+D19+E19)/J19) -> 0
A20: 9 | B20: =HYPERLINK("#'UT09_PhanTich_Insights'!A1","ANLY-001") -> ANLY-001 | C20: =UT09_PhanTich_Insights!A7 -> 0 | D20: =UT09_PhanTich_Insights!C7 -> 0 | E20: =UT09_PhanTich_Insights!E7 -> 0 | F20: =UT09_PhanTich_Insights!G7 -> 15 | G20: =UT09_PhanTich_Insights!I7 -> 8 | H20: =UT09_PhanTich_Insights!K7 -> 4 | I20: =UT09_PhanTich_Insights!M7 -> 3 | J20: =UT09_PhanTich_Insights!O7 -> 15 | K20: =IF(J20=0,0,(C20+D20+E20)/J20) -> 0
A21: 10 | B21: =HYPERLINK("#'UT10_AI_TaoSurvey'!A1","AI-GEN-001") -> AI-GEN-001 | C21: =UT10_AI_TaoSurvey!A7 -> 0 | D21: =UT10_AI_TaoSurvey!C7 -> 0 | E21: =UT10_AI_TaoSurvey!E7 -> 0 | F21: =UT10_AI_TaoSurvey!G7 -> 15 | G21: =UT10_AI_TaoSurvey!I7 -> 6 | H21: =UT10_AI_TaoSurvey!K7 -> 5 | I21: =UT10_AI_TaoSurvey!M7 -> 4 | J21: =UT10_AI_TaoSurvey!O7 -> 15 | K21: =IF(J21=0,0,(C21+D21+E21)/J21) -> 0
A22: 11 | B22: =HYPERLINK("#'UT11_AI_Dich'!A1","AI-TR-001") -> AI-TR-001 | C22: =UT11_AI_Dich!A7 -> 0 | D22: =UT11_AI_Dich!C7 -> 0 | E22: =UT11_AI_Dich!E7 -> 0 | F22: =UT11_AI_Dich!G7 -> 12 | G22: =UT11_AI_Dich!I7 -> 4 | H22: =UT11_AI_Dich!K7 -> 7 | I22: =UT11_AI_Dich!M7 -> 1 | J22: =UT11_AI_Dich!O7 -> 12 | K22: =IF(J22=0,0,(C22+D22+E22)/J22) -> 0
A23: 12 | B23: =HYPERLINK("#'UT12_AI_Sentiment'!A1","AI-SEN-001") -> AI-SEN-001 | C23: =UT12_AI_Sentiment!A7 -> 0 | D23: =UT12_AI_Sentiment!C7 -> 0 | E23: =UT12_AI_Sentiment!E7 -> 0 | F23: =UT12_AI_Sentiment!G7 -> 12 | G23: =UT12_AI_Sentiment!I7 -> 6 | H23: =UT12_AI_Sentiment!K7 -> 2 | I23: =UT12_AI_Sentiment!M7 -> 4 | J23: =UT12_AI_Sentiment!O7 -> 12 | K23: =IF(J23=0,0,(C23+D23+E23)/J23) -> 0
A24: 13 | B24: =HYPERLINK("#'UT13_AI_TopicTree'!A1","AI-TOP-001") -> AI-TOP-001 | C24: =UT13_AI_TopicTree!A7 -> 0 | D24: =UT13_AI_TopicTree!C7 -> 0 | E24: =UT13_AI_TopicTree!E7 -> 0 | F24: =UT13_AI_TopicTree!G7 -> 15 | G24: =UT13_AI_TopicTree!I7 -> 6 | H24: =UT13_AI_TopicTree!K7 -> 4 | I24: =UT13_AI_TopicTree!M7 -> 5 | J24: =UT13_AI_TopicTree!O7 -> 15 | K24: =IF(J24=0,0,(C24+D24+E24)/J24) -> 0
A25: 14 | B25: =HYPERLINK("#'UT14_AI_ResultChat'!A1","AI-CHAT-001") -> AI-CHAT-001 | C25: =UT14_AI_ResultChat!A7 -> 0 | D25: =UT14_AI_ResultChat!C7 -> 0 | E25: =UT14_AI_ResultChat!E7 -> 0 | F25: =UT14_AI_ResultChat!G7 -> 10 | G25: =UT14_AI_ResultChat!I7 -> 5 | H25: =UT14_AI_ResultChat!K7 -> 3 | I25: =UT14_AI_ResultChat!M7 -> 2 | J25: =UT14_AI_ResultChat!O7 -> 10 | K25: =IF(J25=0,0,(C25+D25+E25)/J25) -> 0
A26: 15 | B26: =HYPERLINK("#'UT15_TichHop'!A1","INTG-001") -> INTG-001 | C26: =UT15_TichHop!A7 -> 0 | D26: =UT15_TichHop!C7 -> 0 | E26: =UT15_TichHop!E7 -> 0 | F26: =UT15_TichHop!G7 -> 12 | G26: =UT15_TichHop!I7 -> 5 | H26: =UT15_TichHop!K7 -> 7 | I26: =UT15_TichHop!M7 -> 0 | J26: =UT15_TichHop!O7 -> 12 | K26: =IF(J26=0,0,(C26+D26+E26)/J26) -> 0
A27: 16 | B27: =HYPERLINK("#'UT16_API'!A1","API-001") -> API-001 | C27: =UT16_API!A7 -> 0 | D27: =UT16_API!C7 -> 0 | E27: =UT16_API!E7 -> 0 | F27: =UT16_API!G7 -> 12 | G27: =UT16_API!I7 -> 5 | H27: =UT16_API!K7 -> 5 | I27: =UT16_API!M7 -> 2 | J27: =UT16_API!O7 -> 12 | K27: =IF(J27=0,0,(C27+D27+E27)/J27) -> 0
A28: 17 | B28: =HYPERLINK("#'UT17_LuuTru_Email'!A1","STGE-001") -> STGE-001 | C28: =UT17_LuuTru_Email!A7 -> 0 | D28: =UT17_LuuTru_Email!C7 -> 0 | E28: =UT17_LuuTru_Email!E7 -> 0 | F28: =UT17_LuuTru_Email!G7 -> 12 | G28: =UT17_LuuTru_Email!I7 -> 6 | H28: =UT17_LuuTru_Email!K7 -> 5 | I28: =UT17_LuuTru_Email!M7 -> 1 | J28: =UT17_LuuTru_Email!O7 -> 12 | K28: =IF(J28=0,0,(C28+D28+E28)/J28) -> 0
A30: Sub total | C30: =SUM(C12:C28) -> 1 | D30: =SUM(D12:D28) -> 1 | E30: =SUM(E12:E28) -> 1 | F30: =SUM(F12:F28) -> 221 | G30: =SUM(G12:G28) -> 112 | H30: =SUM(H12:H28) -> 72 | I30: =SUM(I12:I28) -> 40 | J30: =SUM(J12:J28) -> 224 | K30: =IF(J30=0,0,(C30+D30+E30)/J30) -> 0.013392857
A32: Test coverage | C32: =IF(J30=0,0,(C30+D30+E30)/J30) -> 0.013392857
A33: Test successful coverage | C33: =IF((C30+D30)=0,0,C30/(C30+D30)) -> 0.5
A34: Normal case coverage | C34: =IF(G30=0,0,SUM(COUNTIFS(UT01_XacThuc!F21:Q21,"N",UT01_XacThuc!F22:Q22,"Passed"),COUNTIFS(UT01_XacThuc!F21:Q21,"N",UT01_XacThuc!F22:Q22,"Failed"),COUNTIFS(UT01_XacThuc!F21:Q21,"N",UT01_XacThuc!F22:Q22,"Blocked"),COUNTIFS(UT02_ToChuc!F21:Q21,"N",UT02_ToChuc!F22:Q22,"Passed"),COUNTIFS(UT02_ToChuc!F21:Q21,"N",UT02_ToChuc!F22:Q22,"Failed"),COUNTIFS(UT02_ToChuc!F21:Q21,"N",UT02_ToChuc!F22:Q22,"Blocked"),COUNTIFS(UT03_Workspace_RBAC!F21:T21,"N",UT03_Workspace_RBAC!F22:T22,"Passed"),COUNTIFS(UT03_Workspace_RBAC!F21:T21,"N",UT03_Workspace_RBAC!F22:T22,"Failed"),COUNTIFS(UT03_Workspace_RBAC!F21:T21,"N",UT03_Workspace_RBAC!F22:T22,"Blocked"),COUNTIFS(UT04_Dashboard_DieuHuong!F21:O21,"N",UT04_Dashboard_DieuHuong!F22:O22,"Passed"),COUNTIFS(UT04_Dashboard_DieuHuong!F21:O21,"N",UT04_Dashboard_DieuHuong!F22:O22,"Failed"),COUNTIFS(UT04_Dashboard_DieuHuong!F21:O21,"N",UT04_Dashboard_DieuHuong!F22:O22,"Blocked"),COUNTIFS(UT05_Survey_ThuCong!F21:T21,"N",UT05_Survey_ThuCong!F22:T22,"Passed"),COUNTIFS(UT05_Survey_ThuCong!F21:T21,"N",UT05_Survey_ThuCong!F22:T22,"Failed"),COUNTIFS(UT05_Survey_ThuCong!F21:T21,"N",UT05_Survey_ThuCong!F22:T22,"Blocked"),COUNTIFS(UT06_Import_CSV_XLSX!F21:T21,"N",UT06_Import_CSV_XLSX!F22:T22,"Passed"),COUNTIFS(UT06_Import_CSV_XLSX!F21:T21,"N",UT06_Import_CSV_XLSX!F22:T22,"Failed"),COUNTIFS(UT06_Import_CSV_XLSX!F21:T21,"N",UT06_Import_CSV_XLSX!F22:T22,"Blocked"),COUNTIFS(UT07_TestBank_Adaptive!F21:T21,"N",UT07_TestBank_Adaptive!F22:T22,"Passed"),COUNTIFS(UT07_TestBank_Adaptive!F21:T21,"N",UT07_TestBank_Adaptive!F22:T22,"Failed"),COUNTIFS(UT07_TestBank_Adaptive!F21:T21,"N",UT07_TestBank_Adaptive!F22:T22,"Blocked"),COUNTIFS(UT08_PhanHoi!F21:T21,"N",UT08_PhanHoi!F22:T22,"Passed"),COUNTIFS(UT08_PhanHoi!F21:T21,"N",UT08_PhanHoi!F22:T22,"Failed"),COUNTIFS(UT08_PhanHoi!F21:T21,"N",UT08_PhanHoi!F22:T22,"Blocked"),COUNTIFS(UT09_PhanTich_Insights!F21:T21,"N",UT09_PhanTich_Insights!F22:T22,"Passed"),COUNTIFS(UT09_PhanTich_Insights!F21:T21,"N",UT09_PhanTich_Insights!F22:T22,"Failed"),COUNTIFS(UT09_PhanTich_Insights!F21:T21,"N",UT09_PhanTich_Insights!F22:T22,"Blocked"),COUNTIFS(UT10_AI_TaoSurvey!F21:T21,"N",UT10_AI_TaoSurvey!F22:T22,"Passed"),COUNTIFS(UT10_AI_TaoSurvey!F21:T21,"N",UT10_AI_TaoSurvey!F22:T22,"Failed"),COUNTIFS(UT10_AI_TaoSurvey!F21:T21,"N",UT10_AI_TaoSurvey!F22:T22,"Blocked"),COUNTIFS(UT11_AI_Dich!F21:Q21,"N",UT11_AI_Dich!F22:Q22,"Passed"),COUNTIFS(UT11_AI_Dich!F21:Q21,"N",UT11_AI_Dich!F22:Q22,"Failed"),COUNTIFS(UT11_AI_Dich!F21:Q21,"N",UT11_AI_Dich!F22:Q22,"Blocked"),COUNTIFS(UT12_AI_Sentiment!F21:Q21,"N",UT12_AI_Sentiment!F22:Q22,"Passed"),COUNTIFS(UT12_AI_Sentiment!F21:Q21,"N",UT12_AI_Sentiment!F22:Q22,"Failed"),COUNTIFS(UT12_AI_Sentiment!F21:Q21,"N",UT12_AI_Sentiment!F22:Q22,"Blocked"),COUNTIFS(UT13_AI_TopicTree!F21:T21,"N",UT13_AI_TopicTree!F22:T22,"Passed"),COUNTIFS(UT13_AI_TopicTree!F21:T21,"N",UT13_AI_TopicTree!F22:T22,"Failed"),COUNTIFS(UT13_AI_TopicTree!F21:T21,"N",UT13_AI_TopicTree!F22:T22,"Blocked"),COUNTIFS(UT14_AI_ResultChat!F21:O21,"N",UT14_AI_ResultChat!F22:O22,"Passed"),COUNTIFS(UT14_AI_ResultChat!F21:O21,"N",UT14_AI_ResultChat!F22:O22,"Failed"),COUNTIFS(UT14_AI_ResultChat!F21:O21,"N",UT14_AI_ResultChat!F22:O22,"Blocked"),COUNTIFS(UT15_TichHop!F21:Q21,"N",UT15_TichHop!F22:Q22,"Passed"),COUNTIFS(UT15_TichHop!F21:Q21,"N",UT15_TichHop!F22:Q22,"Failed"),COUNTIFS(UT15_TichHop!F21:Q21,"N",UT15_TichHop!F22:Q22,"Blocked"),COUNTIFS(UT16_API!F21:Q21,"N",UT16_API!F22:Q22,"Passed"),COUNTIFS(UT16_API!F21:Q21,"N",UT16_API!F22:Q22,"Failed"),COUNTIFS(UT16_API!F21:Q21,"N",UT16_API!F22:Q22,"Blocked"),COUNTIFS(UT17_LuuTru_Email!F21:Q21,"N",UT17_LuuTru_Email!F22:Q22,"Passed"),COUNTIFS(UT17_LuuTru_Email!F21:Q21,"N",UT17_LuuTru_Email!F22:Q22,"Failed"),COUNTIFS(UT17_LuuTru_Email!F21:Q21,"N",UT17_LuuTru_Email!F22:Q22,"Blocked"))/G30) -> 0.0089285714
A35: Abnormal case coverage | C35: =IF(H30=0,0,SUM(COUNTIFS(UT01_XacThuc!F21:Q21,"A",UT01_XacThuc!F22:Q22,"Passed"),COUNTIFS(UT01_XacThuc!F21:Q21,"A",UT01_XacThuc!F22:Q22,"Failed"),COUNTIFS(UT01_XacThuc!F21:Q21,"A",UT01_XacThuc!F22:Q22,"Blocked"),COUNTIFS(UT02_ToChuc!F21:Q21,"A",UT02_ToChuc!F22:Q22,"Passed"),COUNTIFS(UT02_ToChuc!F21:Q21,"A",UT02_ToChuc!F22:Q22,"Failed"),COUNTIFS(UT02_ToChuc!F21:Q21,"A",UT02_ToChuc!F22:Q22,"Blocked"),COUNTIFS(UT03_Workspace_RBAC!F21:T21,"A",UT03_Workspace_RBAC!F22:T22,"Passed"),COUNTIFS(UT03_Workspace_RBAC!F21:T21,"A",UT03_Workspace_RBAC!F22:T22,"Failed"),COUNTIFS(UT03_Workspace_RBAC!F21:T21,"A",UT03_Workspace_RBAC!F22:T22,"Blocked"),COUNTIFS(UT04_Dashboard_DieuHuong!F21:O21,"A",UT04_Dashboard_DieuHuong!F22:O22,"Passed"),COUNTIFS(UT04_Dashboard_DieuHuong!F21:O21,"A",UT04_Dashboard_DieuHuong!F22:O22,"Failed"),COUNTIFS(UT04_Dashboard_DieuHuong!F21:O21,"A",UT04_Dashboard_DieuHuong!F22:O22,"Blocked"),COUNTIFS(UT05_Survey_ThuCong!F21:T21,"A",UT05_Survey_ThuCong!F22:T22,"Passed"),COUNTIFS(UT05_Survey_ThuCong!F21:T21,"A",UT05_Survey_ThuCong!F22:T22,"Failed"),COUNTIFS(UT05_Survey_ThuCong!F21:T21,"A",UT05_Survey_ThuCong!F22:T22,"Blocked"),COUNTIFS(UT06_Import_CSV_XLSX!F21:T21,"A",UT06_Import_CSV_XLSX!F22:T22,"Passed"),COUNTIFS(UT06_Import_CSV_XLSX!F21:T21,"A",UT06_Import_CSV_XLSX!F22:T22,"Failed"),COUNTIFS(UT06_Import_CSV_XLSX!F21:T21,"A",UT06_Import_CSV_XLSX!F22:T22,"Blocked"),COUNTIFS(UT07_TestBank_Adaptive!F21:T21,"A",UT07_TestBank_Adaptive!F22:T22,"Passed"),COUNTIFS(UT07_TestBank_Adaptive!F21:T21,"A",UT07_TestBank_Adaptive!F22:T22,"Failed"),COUNTIFS(UT07_TestBank_Adaptive!F21:T21,"A",UT07_TestBank_Adaptive!F22:T22,"Blocked"),COUNTIFS(UT08_PhanHoi!F21:T21,"A",UT08_PhanHoi!F22:T22,"Passed"),COUNTIFS(UT08_PhanHoi!F21:T21,"A",UT08_PhanHoi!F22:T22,"Failed"),COUNTIFS(UT08_PhanHoi!F21:T21,"A",UT08_PhanHoi!F22:T22,"Blocked"),COUNTIFS(UT09_PhanTich_Insights!F21:T21,"A",UT09_PhanTich_Insights!F22:T22,"Passed"),COUNTIFS(UT09_PhanTich_Insights!F21:T21,"A",UT09_PhanTich_Insights!F22:T22,"Failed"),COUNTIFS(UT09_PhanTich_Insights!F21:T21,"A",UT09_PhanTich_Insights!F22:T22,"Blocked"),COUNTIFS(UT10_AI_TaoSurvey!F21:T21,"A",UT10_AI_TaoSurvey!F22:T22,"Passed"),COUNTIFS(UT10_AI_TaoSurvey!F21:T21,"A",UT10_AI_TaoSurvey!F22:T22,"Failed"),COUNTIFS(UT10_AI_TaoSurvey!F21:T21,"A",UT10_AI_TaoSurvey!F22:T22,"Blocked"),COUNTIFS(UT11_AI_Dich!F21:Q21,"A",UT11_AI_Dich!F22:Q22,"Passed"),COUNTIFS(UT11_AI_Dich!F21:Q21,"A",UT11_AI_Dich!F22:Q22,"Failed"),COUNTIFS(UT11_AI_Dich!F21:Q21,"A",UT11_AI_Dich!F22:Q22,"Blocked"),COUNTIFS(UT12_AI_Sentiment!F21:Q21,"A",UT12_AI_Sentiment!F22:Q22,"Passed"),COUNTIFS(UT12_AI_Sentiment!F21:Q21,"A",UT12_AI_Sentiment!F22:Q22,"Failed"),COUNTIFS(UT12_AI_Sentiment!F21:Q21,"A",UT12_AI_Sentiment!F22:Q22,"Blocked"),COUNTIFS(UT13_AI_TopicTree!F21:T21,"A",UT13_AI_TopicTree!F22:T22,"Passed"),COUNTIFS(UT13_AI_TopicTree!F21:T21,"A",UT13_AI_TopicTree!F22:T22,"Failed"),COUNTIFS(UT13_AI_TopicTree!F21:T21,"A",UT13_AI_TopicTree!F22:T22,"Blocked"),COUNTIFS(UT14_AI_ResultChat!F21:O21,"A",UT14_AI_ResultChat!F22:O22,"Passed"),COUNTIFS(UT14_AI_ResultChat!F21:O21,"A",UT14_AI_ResultChat!F22:O22,"Failed"),COUNTIFS(UT14_AI_ResultChat!F21:O21,"A",UT14_AI_ResultChat!F22:O22,"Blocked"),COUNTIFS(UT15_TichHop!F21:Q21,"A",UT15_TichHop!F22:Q22,"Passed"),COUNTIFS(UT15_TichHop!F21:Q21,"A",UT15_TichHop!F22:Q22,"Failed"),COUNTIFS(UT15_TichHop!F21:Q21,"A",UT15_TichHop!F22:Q22,"Blocked"),COUNTIFS(UT16_API!F21:Q21,"A",UT16_API!F22:Q22,"Passed"),COUNTIFS(UT16_API!F21:Q21,"A",UT16_API!F22:Q22,"Failed"),COUNTIFS(UT16_API!F21:Q21,"A",UT16_API!F22:Q22,"Blocked"),COUNTIFS(UT17_LuuTru_Email!F21:Q21,"A",UT17_LuuTru_Email!F22:Q22,"Passed"),COUNTIFS(UT17_LuuTru_Email!F21:Q21,"A",UT17_LuuTru_Email!F22:Q22,"Failed"),COUNTIFS(UT17_LuuTru_Email!F21:Q21,"A",UT17_LuuTru_Email!F22:Q22,"Blocked"))/H30) -> 0.027777778
A36: Boundary case coverage | C36: =IF(I30=0,0,SUM(COUNTIFS(UT01_XacThuc!F21:Q21,"B",UT01_XacThuc!F22:Q22,"Passed"),COUNTIFS(UT01_XacThuc!F21:Q21,"B",UT01_XacThuc!F22:Q22,"Failed"),COUNTIFS(UT01_XacThuc!F21:Q21,"B",UT01_XacThuc!F22:Q22,"Blocked"),COUNTIFS(UT02_ToChuc!F21:Q21,"B",UT02_ToChuc!F22:Q22,"Passed"),COUNTIFS(UT02_ToChuc!F21:Q21,"B",UT02_ToChuc!F22:Q22,"Failed"),COUNTIFS(UT02_ToChuc!F21:Q21,"B",UT02_ToChuc!F22:Q22,"Blocked"),COUNTIFS(UT03_Workspace_RBAC!F21:T21,"B",UT03_Workspace_RBAC!F22:T22,"Passed"),COUNTIFS(UT03_Workspace_RBAC!F21:T21,"B",UT03_Workspace_RBAC!F22:T22,"Failed"),COUNTIFS(UT03_Workspace_RBAC!F21:T21,"B",UT03_Workspace_RBAC!F22:T22,"Blocked"),COUNTIFS(UT04_Dashboard_DieuHuong!F21:O21,"B",UT04_Dashboard_DieuHuong!F22:O22,"Passed"),COUNTIFS(UT04_Dashboard_DieuHuong!F21:O21,"B",UT04_Dashboard_DieuHuong!F22:O22,"Failed"),COUNTIFS(UT04_Dashboard_DieuHuong!F21:O21,"B",UT04_Dashboard_DieuHuong!F22:O22,"Blocked"),COUNTIFS(UT05_Survey_ThuCong!F21:T21,"B",UT05_Survey_ThuCong!F22:T22,"Passed"),COUNTIFS(UT05_Survey_ThuCong!F21:T21,"B",UT05_Survey_ThuCong!F22:T22,"Failed"),COUNTIFS(UT05_Survey_ThuCong!F21:T21,"B",UT05_Survey_ThuCong!F22:T22,"Blocked"),COUNTIFS(UT06_Import_CSV_XLSX!F21:T21,"B",UT06_Import_CSV_XLSX!F22:T22,"Passed"),COUNTIFS(UT06_Import_CSV_XLSX!F21:T21,"B",UT06_Import_CSV_XLSX!F22:T22,"Failed"),COUNTIFS(UT06_Import_CSV_XLSX!F21:T21,"B",UT06_Import_CSV_XLSX!F22:T22,"Blocked"),COUNTIFS(UT07_TestBank_Adaptive!F21:T21,"B",UT07_TestBank_Adaptive!F22:T22,"Passed"),COUNTIFS(UT07_TestBank_Adaptive!F21:T21,"B",UT07_TestBank_Adaptive!F22:T22,"Failed"),COUNTIFS(UT07_TestBank_Adaptive!F21:T21,"B",UT07_TestBank_Adaptive!F22:T22,"Blocked"),COUNTIFS(UT08_PhanHoi!F21:T21,"B",UT08_PhanHoi!F22:T22,"Passed"),COUNTIFS(UT08_PhanHoi!F21:T21,"B",UT08_PhanHoi!F22:T22,"Failed"),COUNTIFS(UT08_PhanHoi!F21:T21,"B",UT08_PhanHoi!F22:T22,"Blocked"),COUNTIFS(UT09_PhanTich_Insights!F21:T21,"B",UT09_PhanTich_Insights!F22:T22,"Passed"),COUNTIFS(UT09_PhanTich_Insights!F21:T21,"B",UT09_PhanTich_Insights!F22:T22,"Failed"),COUNTIFS(UT09_PhanTich_Insights!F21:T21,"B",UT09_PhanTich_Insights!F22:T22,"Blocked"),COUNTIFS(UT10_AI_TaoSurvey!F21:T21,"B",UT10_AI_TaoSurvey!F22:T22,"Passed"),COUNTIFS(UT10_AI_TaoSurvey!F21:T21,"B",UT10_AI_TaoSurvey!F22:T22,"Failed"),COUNTIFS(UT10_AI_TaoSurvey!F21:T21,"B",UT10_AI_TaoSurvey!F22:T22,"Blocked"),COUNTIFS(UT11_AI_Dich!F21:Q21,"B",UT11_AI_Dich!F22:Q22,"Passed"),COUNTIFS(UT11_AI_Dich!F21:Q21,"B",UT11_AI_Dich!F22:Q22,"Failed"),COUNTIFS(UT11_AI_Dich!F21:Q21,"B",UT11_AI_Dich!F22:Q22,"Blocked"),COUNTIFS(UT12_AI_Sentiment!F21:Q21,"B",UT12_AI_Sentiment!F22:Q22,"Passed"),COUNTIFS(UT12_AI_Sentiment!F21:Q21,"B",UT12_AI_Sentiment!F22:Q22,"Failed"),COUNTIFS(UT12_AI_Sentiment!F21:Q21,"B",UT12_AI_Sentiment!F22:Q22,"Blocked"),COUNTIFS(UT13_AI_TopicTree!F21:T21,"B",UT13_AI_TopicTree!F22:T22,"Passed"),COUNTIFS(UT13_AI_TopicTree!F21:T21,"B",UT13_AI_TopicTree!F22:T22,"Failed"),COUNTIFS(UT13_AI_TopicTree!F21:T21,"B",UT13_AI_TopicTree!F22:T22,"Blocked"),COUNTIFS(UT14_AI_ResultChat!F21:O21,"B",UT14_AI_ResultChat!F22:O22,"Passed"),COUNTIFS(UT14_AI_ResultChat!F21:O21,"B",UT14_AI_ResultChat!F22:O22,"Failed"),COUNTIFS(UT14_AI_ResultChat!F21:O21,"B",UT14_AI_ResultChat!F22:O22,"Blocked"),COUNTIFS(UT15_TichHop!F21:Q21,"B",UT15_TichHop!F22:Q22,"Passed"),COUNTIFS(UT15_TichHop!F21:Q21,"B",UT15_TichHop!F22:Q22,"Failed"),COUNTIFS(UT15_TichHop!F21:Q21,"B",UT15_TichHop!F22:Q22,"Blocked"),COUNTIFS(UT16_API!F21:Q21,"B",UT16_API!F22:Q22,"Passed"),COUNTIFS(UT16_API!F21:Q21,"B",UT16_API!F22:Q22,"Failed"),COUNTIFS(UT16_API!F21:Q21,"B",UT16_API!F22:Q22,"Blocked"),COUNTIFS(UT17_LuuTru_Email!F21:Q21,"B",UT17_LuuTru_Email!F22:Q22,"Passed"),COUNTIFS(UT17_LuuTru_Email!F21:Q21,"B",UT17_LuuTru_Email!F22:Q22,"Failed"),COUNTIFS(UT17_LuuTru_Email!F21:Q21,"B",UT17_LuuTru_Email!F22:Q22,"Blocked"))/I30) -> 0
A37: Release status | C37: =IF((C30+D30+E30)=0,"CHƯA THỰC HIỆN",IF(D30>0,"CHƯA CHẤP NHẬN",IF(E30>0,"CÒN BLOCKED - CẦN QUYẾT ĐỊNH",IF(F30>0,"ĐANG THỰC HIỆN","SẴN SÀNG SIGN-OFF")))) -> CHƯA CHẤP NHẬN

Sheet UT01_XacThuc
A2: Function Code | C2: AUTH-001 | F2: Function Name | H2: Xác thực & Phiên đăng nhập | W2: BẢNG PHÂN LỚP TƯƠNG ĐƯƠNG & GIÁ TRỊ BIÊN
A3: Created By | C3: QA / UAT Team | F3: Executed By | W3: Điều kiện (Condition) | X3: VP – Lớp hợp lệ | Y3: IP – Lớp không hợp lệ | Z3: VB – Biên hợp lệ | AA3: IB – Ngoài biên
A4: Source / Status | C4: Verified | https://github.com/Royal2005-coder/formailab/tree/ef92d78aa86916e6fbf4bc8a43044a4a4328154d/apps/web/modules/auth | W4: Thông tin đăng nhập | X4: Email tồn tại + mật khẩu đúng | Y4: Email không tồn tại / mật khẩu sai | Z4: Dữ liệu vừa đủ để form cho submit | AA4: Bỏ trống trường bắt buộc
A5: Test requirement | C5: Kiểm tra đăng nhập, đăng ký, quên mật khẩu, OAuth, đăng xuất và bảo vệ route. | W5: Định dạng email | X5: Email đúng cú pháp | Y5: Email sai cú pháp | Z5: Địa chỉ ngắn nhất vẫn đúng cú pháp theo validator | AA5: Thiếu phần local/domain
A6: Passed | C6: Failed | E6: Blocked | G6: Untested | I6: N | K6: A | M6: B | O6: Total Test Cases | W6: Mật khẩu | X6: Đạt chính sách hệ thống | Y6: Không đạt chính sách | Z6: Đúng ngưỡng tối thiểu theo cấu hình | AA6: Ngắn hơn ngưỡng 1 ký tự
A7: =COUNTIF(F22:Q22,"Passed") -> 1 | C7: =COUNTIF(F22:Q22,"Failed") -> 1 | E7: =COUNTIF(F22:Q22,"Blocked") -> 1 | G7: =12-A7-C7-E7 -> 9 | I7: =COUNTIF(F21:Q21,"N") -> 5 | K7: =COUNTIF(F21:Q21,"A") -> 5 | M7: =COUNTIF(F21:Q21,"B") -> 2 | O7: 12 | W7: Token đặt lại mật khẩu | X7: Token hợp lệ, còn hiệu lực | Y7: Token sai / đã dùng | Z7: Ngay trước thời điểm hết hạn | AA7: Vừa quá thời điểm hết hạn
W8: Phiên đăng nhập | X8: Session hợp lệ | Y8: Session không tồn tại | Z8: Ngay trước khi session hết hiệu lực | AA8: Session đã hết hiệu lực
F9: AUTH-001 | G9: AUTH-002 | H9: AUTH-003 | I9: AUTH-004 | J9: AUTH-005 | K9: AUTH-006 | L9: AUTH-007 | M9: AUTH-008 | N9: AUTH-009 | O9: AUTH-010 | P9: AUTH-011 | Q9: AUTH-012 | W9: Quy ước: VP = Valid Partition (phân lớp hợp lệ); IP = Invalid Partition (phân lớp không hợp lệ); VB = Valid Boundary (giá trị biên hợp lệ); IB = Invalid/Outside Boundary (ngay ngoài biên). Nếu chức năng không có ngưỡng số cố định, biên được xác định theo validator/quyền/trạng thái cấu hình của hệ thống.
A10: Condition | B10: Tình huống | F10: Đăng nhập đúng email và mật khẩu | G10: Sai mật khẩu | H10: Email chưa đăng ký | I10: Bỏ trống trường bắt buộc | J10: Đăng xuất | K10: Đăng ký tài khoản hợp lệ | L10: Đăng ký bằng email đã tồn tại | M10: Mật khẩu không đạt yêu cầu | N10: Yêu cầu quên mật khẩu | O10: Reset link hết hạn/không hợp lệ | P10: Đăng nhập OAuth thành công | Q10: Truy cập route bảo vệ khi chưa đăng nhập
B11: Tiền điều kiện | F11: Có tài khoản đang hoạt động | G11: Có tài khoản hợp lệ | H11: Không có tài khoản tương ứng | I11: Trang đăng nhập mở được | J11: Đã đăng nhập | K11: Cho phép đăng ký | L11: Email đã có tài khoản | M11: Cho phép đăng ký/đổi mật khẩu | N11: Email tồn tại; SMTP test hoạt động | O11: Có link reset lỗi/hết hạn | P11: OAuth test cấu hình | Q11: Không có session
B12: Input 1 | F12: Email + mật khẩu hợp lệ | G12: Email đúng | H12: Email chưa tồn tại | I12: Email hoặc mật khẩu trống | J12: Thao tác Đăng xuất | K12: Email mới hợp lệ | L12: Email trùng | M12: Mật khẩu quá ngắn/yếu | N12: Email hợp lệ | O12: Token hết hạn | P12: Provider hợp lệ | Q12: URL workspace/survey bảo vệ | W12: BẢNG DỮ LIỆU MẪU THỰC THI — KHÔNG TẠO TEST CASE ĐỘC LẬP
B13: Input 2 | F13: Tài khoản active | G13: Mật khẩu sai | H13: Mật khẩu bất kỳ | I13: - | J13: Session hiện tại | K13: Mật khẩu đạt yêu cầu | L13: Mật khẩu hợp lệ | M13: Email hợp lệ | N13: Forgot password | O13: Mật khẩu mới hợp lệ | P13: User cho phép consent | Q13: - | W13: # | X13: Loại test case | Y13: Dữ liệu nhập / thao tác mẫu | Z13: Kết quả mong đợi | AA13: TC ID
A14: Confirm | B14: Bước 1 | F14: Mở trang Đăng nhập | G14: Mở trang Đăng nhập | H14: Mở Đăng nhập | I14: Để trống một trường | J14: Mở menu tài khoản | K14: Mở Đăng ký | L14: Mở Đăng ký | M14: Nhập mật khẩu không đạt chuẩn | N14: Mở Quên mật khẩu | O14: Mở link reset | P14: Chọn đăng nhập OAuth | Q14: Mở trực tiếp URL bảo vệ | W14: 1 | X14: N – Bình thường | Y14: Input 1: Email + mật khẩu hợp lệ | Input 2: Tài khoản active | Z14: Đăng nhập thành công và vào đúng workspace. | AA14: AUTH-001
B15: Bước 2 | F15: Nhập email và mật khẩu | G15: Nhập email đúng và mật khẩu sai | H15: Nhập dữ liệu | I15: Bấm Đăng nhập | J15: Bấm Đăng xuất | K15: Nhập thông tin | L15: Nhập email trùng | M15: Submit | N15: Nhập email | O15: Nhập mật khẩu mới | P15: Hoàn tất consent | Q15: Quan sát redirect | W15: 2 | X15: A – Bất thường | Y15: Input 1: Email đúng | Input 2: Mật khẩu sai | Z15: Không đăng nhập; thông báo lỗi rõ ràng. | AA15: AUTH-002
B16: Bước 3 | F16: Bấm Đăng nhập | G16: Bấm Đăng nhập | H16: Bấm Đăng nhập | I16: Quan sát validation | J16: Chờ redirect | K16: Xác nhận đăng ký | L16: Bấm tạo tài khoản | M16: Đọc validation | N16: Gửi yêu cầu | O16: Submit | P16: Chờ callback | Q16: Không đăng nhập | W16: 3 | X16: A – Bất thường | Y16: Input 1: Email chưa tồn tại | Input 2: Mật khẩu bất kỳ | Z16: Không đăng nhập; không lộ thông tin nhạy cảm về tài khoản. | AA16: AUTH-003
B17: Bước 4 | F17: Mở một trang trong workspace | G17: Quan sát thông báo | H17: Quan sát kết quả | I17: Thử lại trường còn lại | J17: Mở lại URL bảo vệ | K17: Thực hiện bước xác minh nếu có | L17: Quan sát thông báo | M17: Sửa thành mật khẩu hợp lệ | N17: Kiểm tra inbox test | O17: Quan sát kết quả | P17: Mở workspace | Q17: Thử refresh | W17: 4 | X17: B – Giá trị biên | Y17: Input 1: Email hoặc mật khẩu trống | Input 2: - | Z17: Form chặn submit và chỉ rõ trường bắt buộc. | AA17: AUTH-004
B18: Kết quả mong đợi | F18: Đăng nhập thành công và vào đúng workspace. | G18: Không đăng nhập; thông báo lỗi rõ ràng. | H18: Không đăng nhập; không lộ thông tin nhạy cảm về tài khoản. | I18: Form chặn submit và chỉ rõ trường bắt buộc. | J18: Session bị kết thúc; URL bảo vệ yêu cầu đăng nhập lại. | K18: Tài khoản được tạo theo flow cấu hình. | L18: Không tạo tài khoản thứ hai. | M18: Hệ thống chặn dữ liệu không đạt chính sách và cho phép sửa. | N18: Hệ thống xác nhận và gửi email reset theo cấu hình. | O18: Không đổi mật khẩu; hướng dẫn tạo yêu cầu mới. | P18: Đăng nhập thành công và mapping đúng tài khoản. | Q18: Bị chuyển về đăng nhập/unauthorized; không lộ dữ liệu. | W18: 5 | X18: N – Bình thường | Y18: Input 1: Thao tác Đăng xuất | Input 2: Session hiện tại | Z18: Session bị kết thúc; URL bảo vệ yêu cầu đăng nhập lại. | AA18: AUTH-005
B19: Lỗi / Thông báo | G19: Sai thông tin đăng nhập | H19: Thông tin đăng nhập không hợp lệ | I19: Trường bắt buộc | L19: Email đã được sử dụng hoặc thông báo tương đương | M19: Mật khẩu không hợp lệ | O19: Link không hợp lệ hoặc hết hạn | Q19: Authentication required | W19: 6 | X19: N – Bình thường | Y19: Input 1: Email mới hợp lệ | Input 2: Mật khẩu đạt yêu cầu | Z19: Tài khoản được tạo theo flow cấu hình. | AA19: AUTH-006
B20: Điểm kiểm tra | F20: Không tạo phiên trùng bất thường | G20: Không tạo session | H20: Không lộ dữ liệu user khác | I20: Không gửi request không cần thiết | J20: Không truy cập dữ liệu sau logout | K20: Không tạo trùng | L20: Số user không tăng | M20: Không lưu mật khẩu lỗi | N20: Email/link liên quan đúng user | O20: Mật khẩu cũ vẫn dùng theo trạng thái trước | P20: Không tạo tài khoản trùng ngoài thiết kế | Q20: Không có nội dung riêng tư trong trang | W20: 7 | X20: A – Bất thường | Y20: Input 1: Email trùng | Input 2: Mật khẩu hợp lệ | Z20: Không tạo tài khoản thứ hai. | AA20: AUTH-007
A21: Result | B21: Type (N: Normal, A: Abnormal, B: Boundary) | F21: N | G21: A | H21: A | I21: B | J21: N | K21: N | L21: A | M21: B | N21: N | O21: A | P21: N | Q21: A | W21: 8 | X21: B – Giá trị biên | Y21: Input 1: Mật khẩu quá ngắn/yếu | Input 2: Email hợp lệ | Z21: Hệ thống chặn dữ liệu không đạt chính sách và cho phép sửa. | AA21: AUTH-008
B22: Passed / Failed / Blocked | F22: Passed | G22: Failed | H22: Blocked | W22: 9 | X22: N – Bình thường | Y22: Input 1: Email hợp lệ | Input 2: Forgot password | Z22: Hệ thống xác nhận và gửi email reset theo cấu hình. | AA22: AUTH-009
B23: Executed Date | F23: Ví dụ | G23: Ví dụ | H23: Ví dụ | W23: 10 | X23: A – Bất thường | Y23: Input 1: Token hết hạn | Input 2: Mật khẩu mới hợp lệ | Z23: Không đổi mật khẩu; hướng dẫn tạo yêu cầu mới. | AA23: AUTH-010
B24: Defect ID | F24: Ví dụ | G24: Ví dụ | H24: Ví dụ | W24: 11 | X24: N – Bình thường | Y24: Input 1: Provider hợp lệ | Input 2: User cho phép consent | Z24: Đăng nhập thành công và mapping đúng tài khoản. | AA24: AUTH-011
W25: 12 | X25: A – Bất thường | Y25: Input 1: URL workspace/survey bảo vệ | Input 2: - | Z25: Bị chuyển về đăng nhập/unauthorized; không lộ dữ liệu. | AA25: AUTH-012

Sheet UT02_ToChuc
A2: Function Code | C2: ORG-001 | F2: Function Name | H2: Tổ chức, Thành viên & Nhóm | W2: BẢNG PHÂN LỚP TƯƠNG ĐƯƠNG & GIÁ TRỊ BIÊN
A3: Created By | C3: QA / UAT Team | F3: Executed By | W3: Điều kiện (Condition) | X3: VP – Lớp hợp lệ | Y3: IP – Lớp không hợp lệ | Z3: VB – Biên hợp lệ | AA3: IB – Ngoài biên
A4: Source / Status | C4: Verified | https://github.com/Royal2005-coder/formailab/tree/ef92d78aa86916e6fbf4bc8a43044a4a4328154d/apps/web/modules/organization | W4: Email mời thành viên | X4: Email mới, đúng định dạng | Y4: Email sai / đã là thành viên | Z4: Invitation còn hiệu lực | AA4: Invitation vừa hết hạn
A5: Test requirement | C5: Kiểm tra vòng đời tổ chức, mời thành viên, vai trò, nhóm và quyền quản trị tổ chức. | W5: Vai trò thành viên | X5: Role được phép theo quyền người thao tác | Y5: Role/ thao tác vượt quyền | Z5: Thay đổi role nhưng tổ chức vẫn còn ≥1 owner | AA5: Cố loại/hạ quyền owner cuối cùng
A6: Passed | C6: Failed | E6: Blocked | G6: Untested | I6: N | K6: A | M6: B | O6: Total Test Cases | W6: Số Owner còn lại | X6: ≥2 owner trước khi remove 1 | Y6: Trạng thái không hợp lệ: 0 owner | Z6: 2 owner → remove 1, còn 1 | AA6: 1 owner → cố remove owner cuối
A7: =COUNTIF(F22:Q22,"Passed") -> 0 | C7: =COUNTIF(F22:Q22,"Failed") -> 0 | E7: =COUNTIF(F22:Q22,"Blocked") -> 0 | G7: =12-A7-C7-E7 -> 12 | I7: =COUNTIF(F21:Q21,"N") -> 7 | K7: =COUNTIF(F21:Q21,"A") -> 5 | M7: =COUNTIF(F21:Q21,"B") -> 0 | O7: 12 | W7: Tên tổ chức/nhóm | X7: Có nội dung hợp lệ | Y7: Rỗng / không hợp lệ | Z7: Giá trị vừa đủ theo validator | AA7: Ngoài giới hạn validator
W8: Quy ước: VP = Valid Partition (phân lớp hợp lệ); IP = Invalid Partition (phân lớp không hợp lệ); VB = Valid Boundary (giá trị biên hợp lệ); IB = Invalid/Outside Boundary (ngay ngoài biên). Nếu chức năng không có ngưỡng số cố định, biên được xác định theo validator/quyền/trạng thái cấu hình của hệ thống.
F9: ORG-001 | G9: ORG-002 | H9: ORG-003 | I9: ORG-004 | J9: ORG-005 | K9: ORG-006 | L9: ORG-007 | M9: ORG-008 | N9: ORG-009 | O9: ORG-010 | P9: ORG-011 | Q9: ORG-012
A10: Condition | B10: Tình huống | F10: Tạo tổ chức mới | G10: Đổi tên tổ chức | H10: Mời thành viên bằng email hợp lệ | I10: Mời email đã là thành viên | J10: Chấp nhận lời mời hợp lệ | K10: Invitation hết hạn/không hợp lệ | L10: Đổi vai trò thành viên | M10: Member thường không đổi role người khác | N10: Xóa thành viên khỏi tổ chức | O10: Không cho remove owner cuối cùng | P10: Tạo/đổi tên nhóm hoặc team | Q10: Trang billing chỉ người có quyền truy cập
B11: Tiền điều kiện | F11: User có quyền tạo org | G11: Owner/Manager | H11: Có quyền mời | I11: Email đã thuộc org | J11: Có invitation còn hiệu lực | K11: Có link lỗi/hết hạn | L11: Owner/Manager; có member | M11: Đăng nhập member thường | N11: Owner/Manager; target member | O11: Chỉ còn 1 owner | P11: Org hỗ trợ nhóm/team; có quyền | Q11: Có user manager/member | W11: BẢNG DỮ LIỆU MẪU THỰC THI — KHÔNG TẠO TEST CASE ĐỘC LẬP
B12: Input 1 | F12: Tên tổ chức hợp lệ | G12: Tên mới hợp lệ | H12: Email mới | I12: Email trùng member | J12: Invitation link | K12: Invitation token lỗi | L12: Member hiện tại | M12: Target member | N12: Member cần remove | O12: Owner cuối cùng | P12: Tên nhóm hợp lệ | Q12: Billing settings | W12: # | X12: Loại test case | Y12: Dữ liệu nhập / thao tác mẫu | Z12: Kết quả mong đợi | AA12: TC ID
B13: Input 2 | F13: - | G13: - | H13: Role/member permission | I13: Role bất kỳ | J13: Tài khoản đúng email | K13: - | L13: Role mới | M13: Thao tác đổi role | N13: - | O13: Remove | P13: Members | Q13: Role không phù hợp | W13: 1 | X13: N – Bình thường | Y13: Input 1: Tên tổ chức hợp lệ | Input 2: - | Z13: Tổ chức được tạo và user có quyền owner theo flow. | AA13: ORG-001
A14: Confirm | B14: Bước 1 | F14: Mở tạo tổ chức | G14: Mở Settings tổ chức | H14: Mở Members | I14: Mở Invite | J14: Mở link mời | K14: Mở link | L14: Mở Members | M14: Mở Members | N14: Mở Members | O14: Mở Members | P14: Mở phần Groups/Teams | Q14: Đăng nhập member | W14: 2 | X14: N – Bình thường | Y14: Input 1: Tên mới hợp lệ | Input 2: - | Z14: Tên mới được giữ sau refresh. | AA14: ORG-002
B15: Bước 2 | F15: Nhập tên | G15: Sửa tên | H15: Chọn Invite | I15: Nhập email trùng | J15: Đăng nhập nếu cần | K15: Quan sát thông báo | L15: Chọn thành viên | M15: Tìm control quản trị | N15: Chọn Remove | O15: Thử remove/downgrade owner cuối | P15: Tạo nhóm | Q15: Mở Billing URL/menu | W15: 3 | X15: N – Bình thường | Y15: Input 1: Email mới | Input 2: Role/member permission | Z15: Invitation được tạo/gửi đúng email và role. | AA15: ORG-003
B16: Bước 3 | F16: Bấm Tạo | G16: Lưu | H16: Nhập email/role | I16: Gửi | J16: Chấp nhận | K16: Không thực hiện join | L16: Đổi role | M16: Thử thay đổi nếu UI cho phép | N16: Xác nhận | O16: Xác nhận nếu có | P16: Thêm member | Q16: Quan sát quyền | W16: 4 | X16: A – Bất thường | Y16: Input 1: Email trùng member | Input 2: Role bất kỳ | Z16: Không tạo invitation/member trùng. | AA16: ORG-004
B17: Bước 4 | F17: Mở tổ chức vừa tạo | G17: Refresh trang | H17: Gửi lời mời | I17: Quan sát lỗi | J17: Mở tổ chức | K17: Quay về app | L17: Đăng nhập lại bằng member để kiểm tra | M17: Quan sát kết quả | N17: Target refresh/relogin | O17: Quan sát | P17: Đổi tên và lưu | Q17: Không thay đổi plan | W17: 5 | X17: N – Bình thường | Y17: Input 1: Invitation link | Input 2: Tài khoản đúng email | Z17: User trở thành member đúng org/role. | AA17: ORG-005
B18: Kết quả mong đợi | F18: Tổ chức được tạo và user có quyền owner theo flow. | G18: Tên mới được giữ sau refresh. | H18: Invitation được tạo/gửi đúng email và role. | I18: Không tạo invitation/member trùng. | J18: User trở thành member đúng org/role. | K18: Không thêm member; hiển thị lý do dễ hiểu. | L18: Role mới được áp dụng đúng quyền. | M18: Control bị ẩn/vô hiệu hoặc backend từ chối. | N18: Member bị loại và mất quyền truy cập org. | O18: Hệ thống chặn trạng thái không có owner. | P18: Nhóm/team và membership được lưu đúng. | Q18: User không đủ quyền bị chặn/không thấy thao tác nhạy cảm. | W18: 6 | X18: A – Bất thường | Y18: Input 1: Invitation token lỗi | Input 2: - | Z18: Không thêm member; hiển thị lý do dễ hiểu. | AA18: ORG-006
B19: Lỗi / Thông báo | I19: Thành viên đã tồn tại | K19: Invitation không hợp lệ/hết hạn | M19: Authorization error | O19: Không thể loại owner cuối cùng | Q19: Authorization | W19: 7 | X19: N – Bình thường | Y19: Input 1: Member hiện tại | Input 2: Role mới | Z19: Role mới được áp dụng đúng quyền. | AA19: ORG-007
B20: Điểm kiểm tra | F20: Organization ID mới | G20: Không đổi organization ID | H20: Không tạo member trước khi flow cho phép | I20: Số member không tăng | J20: Invitation chuyển trạng thái hoàn tất | K20: Không lộ org ngoài quyền | L20: Không giữ quyền cũ sau refresh | M20: Không thay role | N20: Không xóa dữ liệu org | O20: Owner vẫn tồn tại | P20: Không tạo duplicate ngoài thiết kế | Q20: Không lộ thông tin thanh toán nhạy cảm | W20: 8 | X20: A – Bất thường | Y20: Input 1: Target member | Input 2: Thao tác đổi role | Z20: Control bị ẩn/vô hiệu hoặc backend từ chối. | AA20: ORG-008
A21: Result | B21: Type (N: Normal, A: Abnormal, B: Boundary) | F21: N | G21: N | H21: N | I21: A | J21: N | K21: A | L21: N | M21: A | N21: N | O21: A | P21: N | Q21: A | W21: 9 | X21: N – Bình thường | Y21: Input 1: Member cần remove | Input 2: - | Z21: Member bị loại và mất quyền truy cập org. | AA21: ORG-009
B22: Passed / Failed / Blocked | W22: 10 | X22: A – Bất thường | Y22: Input 1: Owner cuối cùng | Input 2: Remove | Z22: Hệ thống chặn trạng thái không có owner. | AA22: ORG-010
B23: Executed Date | W23: 11 | X23: N – Bình thường | Y23: Input 1: Tên nhóm hợp lệ | Input 2: Members | Z23: Nhóm/team và membership được lưu đúng. | AA23: ORG-011
B24: Defect ID | W24: 12 | X24: A – Bất thường | Y24: Input 1: Billing settings | Input 2: Role không phù hợp | Z24: User không đủ quyền bị chặn/không thấy thao tác nhạy cảm. | AA24: ORG-012

Sheet UT03_Workspace_RBAC
A2: Function Code | C2: WKSP-001 | F2: Function Name | H2: Workspace & Phân quyền truy cập | W2: BẢNG PHÂN LỚP TƯƠNG ĐƯƠNG & GIÁ TRỊ BIÊN
A3: Created By | C3: QA / UAT Team | F3: Executed By | W3: Điều kiện (Condition) | X3: VP – Lớp hợp lệ | Y3: IP – Lớp không hợp lệ | Z3: VB – Biên hợp lệ | AA3: IB – Ngoài biên
A4: Source / Status | C4: Verified | https://github.com/Royal2005-coder/formailab/tree/ef92d78aa86916e6fbf4bc8a43044a4a4328154d/apps/web/app/(app)/workspaces | W4: Quyền workspace | X4: readWrite/owner/manager đúng phạm vi | Y4: Không có quyền | Z4: read: chỉ được xem | AA4: Cross-workspace / URL ngoài phạm vi
A5: Test requirement | C5: Kiểm tra CRUD workspace, chuyển context, read/readWrite và cách ly dữ liệu giữa workspace. | W5: Truy cập workspace | X5: Workspace tồn tại và user có access | Y5: Workspace không tồn tại / không access | Z5: Refresh đúng workspace hiện tại | AA5: Mở trực tiếp workspace khác
A6: Passed | C6: Failed | E6: Blocked | G6: Untested | I6: N | K6: A | M6: B | O6: Total Test Cases | W6: Thao tác ghi | X6: User có readWrite | Y6: User chỉ read/no access | Z6: Quyền vừa bị đổi readWrite → read | AA6: Tiếp tục dùng quyền cũ sau khi đã bị thu hồi
A7: =COUNTIF(F22:T22,"Passed") -> 0 | C7: =COUNTIF(F22:T22,"Failed") -> 0 | E7: =COUNTIF(F22:T22,"Blocked") -> 0 | G7: =15-A7-C7-E7 -> 15 | I7: =COUNTIF(F21:T21,"N") -> 9 | K7: =COUNTIF(F21:T21,"A") -> 4 | M7: =COUNTIF(F21:T21,"B") -> 2 | O7: 15 | W7: Xóa workspace | X7: Đúng workspace + xác nhận | Y7: Sai workspace / không đủ quyền | Z7: Hủy ở modal xác nhận | AA7: Cố xóa bằng user không có quyền
W8: Quy ước: VP = Valid Partition (phân lớp hợp lệ); IP = Invalid Partition (phân lớp không hợp lệ); VB = Valid Boundary (giá trị biên hợp lệ); IB = Invalid/Outside Boundary (ngay ngoài biên). Nếu chức năng không có ngưỡng số cố định, biên được xác định theo validator/quyền/trạng thái cấu hình của hệ thống.
F9: WKSP-001 | G9: WKSP-002 | H9: WKSP-003 | I9: WKSP-004 | J9: WKSP-005 | K9: WKSP-006 | L9: WKSP-007 | M9: WKSP-008 | N9: WKSP-009 | O9: WKSP-010 | P9: WKSP-011 | Q9: WKSP-012 | R9: WKSP-013 | S9: WKSP-014 | T9: WKSP-015
A10: Condition | B10: Tình huống | F10: Tạo workspace | G10: Đổi tên workspace | H10: Chuyển giữa workspace A và B | I10: Read-only xem danh sách survey | J10: Read-only không tạo survey | K10: readWrite tạo/sửa survey được | L10: Owner/Manager sử dụng AI LAB import | M10: Cross-workspace URL bị chặn | N10: Workspace ID không tồn tại | O10: Xóa workspace có xác nhận | P10: Hủy xóa workspace | Q10: Đổi quyền readWrite → read có hiệu lực | R10: Xóa user khỏi workspace thu hồi quyền | S10: Dữ liệu survey cách ly giữa A/B | T10: Refresh giữ đúng workspace context
B11: Tiền điều kiện | F11: Có quyền quản trị tổ chức | G11: Có quyền ghi | H11: User có quyền cả A/B | I11: Permission=read | J11: Permission=read | K11: Permission=readWrite | L11: Role owner/manager hoặc readWrite | M11: User chỉ có A | N11: Đăng nhập | O11: Owner; workspace có thể xóa | P11: Modal delete đang mở | Q11: Admin có thể đổi permission | R11: User đang có quyền | S11: A/B đều có survey | T11: Đang ở route workspace sâu | W11: BẢNG DỮ LIỆU MẪU THỰC THI — KHÔNG TẠO TEST CASE ĐỘC LẬP
B12: Input 1 | F12: Tên workspace hợp lệ | G12: Tên mới | H12: Workspace A | I12: Workspace A | J12: Create survey | K12: Survey draft | L12: File CSV hợp lệ | M12: URL workspace B | N12: workspaceId giả | O12: Workspace test | P12: Cancel | Q12: Member | R12: Member | S12: Survey A | T12: Route survey/analysis | W12: # | X12: Loại test case | Y12: Dữ liệu nhập / thao tác mẫu | Z12: Kết quả mong đợi | AA12: TC ID
B13: Input 2 | F13: Org hiện tại | G13: Workspace A | H13: Workspace B | I13: Surveys | J13: Workspace A | K13: Workspace A | L13: Workspace A | M13: - | N13: URL trực tiếp | O13: Confirm text/modal | P13: Workspace test | Q13: readWrite → read | R13: Remove access | S13: Workspace B | T13: Refresh | W13: 1 | X13: N – Bình thường | Y13: Input 1: Tên workspace hợp lệ | Input 2: Org hiện tại | Z13: Workspace mới xuất hiện và vào được. | AA13: WKSP-001
A14: Confirm | B14: Bước 1 | F14: Mở tạo workspace | G14: Mở Workspace settings | H14: Mở A | I14: Đăng nhập read-only | J14: Đăng nhập read-only | K14: Đăng nhập readWrite | L14: Mở AI LAB import | M14: Đăng nhập user A | N14: Nhập URL sai ID | O14: Mở Settings | P14: Mở Delete | Q14: Admin đổi permission | R14: Admin remove user | S14: Mở B | T14: Mở route | W14: 2 | X14: N – Bình thường | Y14: Input 1: Tên mới | Input 2: Workspace A | Z14: Tên mới được giữ. | AA14: WKSP-002
B15: Bước 2 | F15: Nhập tên | G15: Đổi tên | H15: Chuyển sang B | I15: Mở workspace | J15: Mở Surveys | K15: Tạo survey | L15: Validate file | M15: Mở URL B trực tiếp | N15: Mở | O15: Chọn Delete | P15: Bấm Cancel | Q15: Member refresh/relogin | R15: User refresh | S15: Tìm ID/tên survey A | T15: Refresh trình duyệt | W15: 3 | X15: N – Bình thường | Y15: Input 1: Workspace A | Input 2: Workspace B | Z15: Context và dữ liệu thay đổi đúng workspace. | AA15: WKSP-003
B16: Bước 3 | F16: Bấm Tạo | G16: Lưu | H16: Kiểm tra route/dữ liệu | I16: Mở Surveys | J16: Tìm/nhấn Create | K16: Sửa một câu | L16: Commit | M16: Quan sát | N16: Quan sát | O16: Xác nhận đúng | P16: Refresh | Q16: Member thử write | R16: User mở workspace URL | S16: Mở direct URL survey A trong context B | T16: Chờ tải | W16: 4 | X16: N – Bình thường | Y16: Input 1: Workspace A | Input 2: Surveys | Z16: User xem được dữ liệu được phép đọc. | AA16: WKSP-004
B17: Bước 4 | F17: Mở workspace | G17: Refresh | H17: Quay lại A | I17: Mở một survey | J17: Quan sát | K17: Lưu | L17: Mở survey mới | M17: Thử route con | N17: Quay lại app | O17: Kiểm tra danh sách | P17: Kiểm tra danh sách | Q17: Member thử read | R17: Quan sát | S17: Quan sát | T17: Kiểm tra breadcrumb/url | W17: 5 | X17: A – Bất thường | Y17: Input 1: Create survey | Input 2: Workspace A | Z17: Nút bị ẩn/vô hiệu hoặc backend từ chối. | AA17: WKSP-005
B18: Kết quả mong đợi | F18: Workspace mới xuất hiện và vào được. | G18: Tên mới được giữ. | H18: Context và dữ liệu thay đổi đúng workspace. | I18: User xem được dữ liệu được phép đọc. | J18: Nút bị ẩn/vô hiệu hoặc backend từ chối. | K18: Thao tác write thành công. | L18: Import được phép theo quyền. | M18: Không xem được dữ liệu B. | N18: Hiển thị not found/redirect an toàn. | O18: Workspace bị xóa theo policy; không còn truy cập. | P18: Workspace vẫn tồn tại nguyên trạng. | Q18: Read vẫn hoạt động; write bị chặn. | R18: Quyền bị thu hồi ngay theo session policy. | S18: Không truy cập survey A từ B trái quyền. | T18: Context không bị nhảy sang workspace mặc định khác. | W18: 6 | X18: N – Bình thường | Y18: Input 1: Survey draft | Input 2: Workspace A | Z18: Thao tác write thành công. | AA18: WKSP-006
B19: Lỗi / Thông báo | J19: Authorization | M19: Authorization/Not found | N19: Không tìm thấy | Q19: Authorization khi write | R19: Authorization | S19: Authorization/Not found | W19: 7 | X19: N – Bình thường | Y19: Input 1: File CSV hợp lệ | Input 2: Workspace A | Z19: Import được phép theo quyền. | AA19: WKSP-007
B20: Điểm kiểm tra | F20: Workspace ID mới | G20: ID không đổi | H20: Không giữ dữ liệu A trên B | I20: Không có thao tác write | J20: Không tạo survey | K20: Dữ liệu thuộc đúng workspace | L20: Audit/context đúng workspace | M20: Không lộ tên/survey B | N20: Không crash toàn app | O20: Không xóa nhầm workspace | P20: Không gọi delete | Q20: Không dùng quyền cache cũ | R20: Không còn data access | S20: Không cross-tenant leak | T20: URL và dữ liệu thống nhất | W20: 8 | X20: A – Bất thường | Y20: Input 1: URL workspace B | Input 2: - | Z20: Không xem được dữ liệu B. | AA20: WKSP-008
A21: Result | B21: Type (N: Normal, A: Abnormal, B: Boundary) | F21: N | G21: N | H21: N | I21: N | J21: A | K21: N | L21: N | M21: A | N21: A | O21: N | P21: B | Q21: N | R21: N | S21: A | T21: B | W21: 9 | X21: A – Bất thường | Y21: Input 1: workspaceId giả | Input 2: URL trực tiếp | Z21: Hiển thị not found/redirect an toàn. | AA21: WKSP-009
B22: Passed / Failed / Blocked | W22: 10 | X22: N – Bình thường | Y22: Input 1: Workspace test | Input 2: Confirm text/modal | Z22: Workspace bị xóa theo policy; không còn truy cập. | AA22: WKSP-010
B23: Executed Date | W23: 11 | X23: B – Giá trị biên | Y23: Input 1: Cancel | Input 2: Workspace test | Z23: Workspace vẫn tồn tại nguyên trạng. | AA23: WKSP-011
B24: Defect ID | W24: 12 | X24: N – Bình thường | Y24: Input 1: Member | Input 2: readWrite → read | Z24: Read vẫn hoạt động; write bị chặn. | AA24: WKSP-012
W25: 13 | X25: N – Bình thường | Y25: Input 1: Member | Input 2: Remove access | Z25: Quyền bị thu hồi ngay theo session policy. | AA25: WKSP-013
W26: 14 | X26: A – Bất thường | Y26: Input 1: Survey A | Input 2: Workspace B | Z26: Không truy cập survey A từ B trái quyền. | AA26: WKSP-014
W27: 15 | X27: B – Giá trị biên | Y27: Input 1: Route survey/analysis | Input 2: Refresh | Z27: Context không bị nhảy sang workspace mặc định khác. | AA27: WKSP-015

Sheet UT04_Dashboard_DieuHuong
A2: Function Code | C2: NAV-001 | F2: Function Name | H2: Dashboard, Danh sách & Điều hướng | W2: BẢNG PHÂN LỚP TƯƠNG ĐƯƠNG & GIÁ TRỊ BIÊN
A3: Created By | C3: QA / UAT Team | F3: Executed By | W3: Điều kiện (Condition) | X3: VP – Lớp hợp lệ | Y3: IP – Lớp không hợp lệ | Z3: VB – Biên hợp lệ | AA3: IB – Ngoài biên
A4: Source / Status | C4: Verified | https://github.com/Royal2005-coder/formailab/tree/ef92d78aa86916e6fbf4bc8a43044a4a4328154d/apps/web/modules/survey/list/components/survey-list.tsx | W4: Số survey trong workspace | X4: ≥1 survey | Y4: Survey ID không tồn tại | Z4: 0 survey → hiển thị empty state | AA4: URL trỏ survey không tồn tại
A5: Test requirement | C5: Kiểm tra hành trình từ workspace đến Surveys, AI LAB, Responses và Analysis. | W5: Context điều hướng | X5: URL và workspace/survey hợp lệ | Y5: Context sai / không quyền | Z5: Refresh tại route sâu | AA5: Back/Forward sang context khác
A6: Passed | C6: Failed | E6: Blocked | G6: Untested | I6: N | K6: A | M6: B | O6: Total Test Cases | W6: Tên survey | X6: Tên trong giới hạn field | Y6: Tên không hợp lệ | Z6: Tên rất dài nhưng vẫn trong giới hạn | AA6: Vượt giới hạn cấu hình
A7: =COUNTIF(F22:O22,"Passed") -> 0 | C7: =COUNTIF(F22:O22,"Failed") -> 0 | E7: =COUNTIF(F22:O22,"Blocked") -> 0 | G7: =10-A7-C7-E7 -> 10 | I7: =COUNTIF(F21:O21,"N") -> 5 | K7: =COUNTIF(F21:O21,"A") -> 1 | M7: =COUNTIF(F21:O21,"B") -> 4 | O7: 10 | W7: Entry point chức năng | X7: Menu/CTA khả dụng theo quyền | Y7: Route không tồn tại | Z7: User read chỉ thấy chức năng đọc | AA7: User read cố mở chức năng ghi
W8: Quy ước: VP = Valid Partition (phân lớp hợp lệ); IP = Invalid Partition (phân lớp không hợp lệ); VB = Valid Boundary (giá trị biên hợp lệ); IB = Invalid/Outside Boundary (ngay ngoài biên). Nếu chức năng không có ngưỡng số cố định, biên được xác định theo validator/quyền/trạng thái cấu hình của hệ thống.
F9: NAV-001 | G9: NAV-002 | H9: NAV-003 | I9: NAV-004 | J9: NAV-005 | K9: NAV-006 | L9: NAV-007 | M9: NAV-008 | N9: NAV-009 | O9: NAV-010
A10: Condition | B10: Tình huống | F10: Mở danh sách khảo sát | G10: Mở survey từ danh sách | H10: Mở luồng tạo survey | I10: Mở AI LAB Survey | J10: Mở Responses/Analysis | K10: Workspace chưa có survey | L10: Tên survey rất dài | M10: Survey ID không tồn tại | N10: Back/Forward trình duyệt | O10: Refresh trang sâu
B11: Tiền điều kiện | F11: Đăng nhập | G11: Có survey | H11: Có quyền tạo | I11: Feature AI LAB khả dụng | J11: Survey có phản hồi | K11: Workspace mới | L11: Có survey tên dài | M11: Đăng nhập | N11: Đã mở nhiều route | O11: Đang ở Analysis hoặc editor | W11: BẢNG DỮ LIỆU MẪU THỰC THI — KHÔNG TẠO TEST CASE ĐỘC LẬP
B12: Input 1 | F12: Workspace hợp lệ | G12: Survey đã tồn tại | H12: Create survey | I12: AI LAB Survey | J12: Responses | K12: 0 survey | L12: 200+ ký tự | M12: surveyId giả | N12: Surveys → AI LAB → Analysis | O12: Refresh | W12: # | X12: Loại test case | Y12: Dữ liệu nhập / thao tác mẫu | Z12: Kết quả mong đợi | AA12: TC ID
